2025-10-23 12:29:30 - telegram_client - ERROR - ❌ Error iniciando listener de Telegram: 'TelegramClient' object has no attribute 'NewMessage'
2025-10-23 12:29:30 - __main__ - ERROR - ❌ Error en bucle principal: 'TelegramClient' object has no attribute 'NewMessage'
2025-10-23 19:19:22 - helpers - ERROR - ❌ Error parseando señal: 'NoneType' object has no attribute 'upper'
2025-10-23 19:21:44 - helpers - ERROR - ❌ Error parseando señal: 'NoneType' object has no attribute 'upper'
2025-10-23 19:39:19 - helpers - ERROR - ❌ Error parseando señal: 'NoneType' object has no attribute 'upper'
2025-10-24 03:18:01 - helpers - ERROR - ❌ Error parseando señal: 'NoneType' object has no attribute 'upper'
2025-10-24 03:19:20 - helpers - ERROR - ❌ Error parseando señal: 'NoneType' object has no attribute 'upper'
2025-10-24 03:21:15 - helpers - ERROR - ❌ Error parseando señal: 'NoneType' object has no attribute 'upper'
2025-10-24 03:21:22 - helpers - ERROR - ❌ Error parseando señal: 'NoneType' object has no attribute 'upper'
2025-10-24 03:29:17 - helpers - ERROR - ❌ Error parseando señal: 'NoneType' object has no attribute 'upper'
2025-10-24 03:35:11 - helpers - ERROR - ❌ Error parseando señal: 'NoneType' object has no attribute 'upper'
2025-10-24 03:37:25 - helpers - ERROR - ❌ Error parseando señal: 'NoneType' object has no attribute 'upper'
2025-10-24 03:42:17 - helpers - ERROR - ❌ Error parseando señal: 'NoneType' object has no attribute 'upper'
2025-10-24 06:58:46 - helpers - ERROR - ❌ Error parseando señal: 'NoneType' object has no attribute 'upper'
2025-10-24 07:02:27 - helpers - ERROR - ❌ Error parseando señal: 'NoneType' object has no attribute 'upper'
2025-10-24 07:02:45 - helpers - ERROR - ❌ Error parseando señal: 'NoneType' object has no attribute 'upper'
2025-10-24 08:01:02 - telethon.network.mtprotosender - ERROR - Automatic reconnection failed 5 time(s)
2025-10-24 08:01:02 - asyncio - ERROR - Future exception was never retrieved
future: <Future finished exception=ConnectionError('Connection to Telegram failed 5 time(s)')>
ConnectionError: Connection to Telegram failed 5 time(s)
2025-10-24 08:01:02 - telegram_client - ERROR - ❌ Error iniciando listener de Telegram: Connection to Telegram failed 5 time(s)
2025-10-24 08:01:02 - __main__ - ERROR - ❌ Error en bucle principal: Connection to Telegram failed 5 time(s)
2025-10-24 08:01:07 - telegram.ext.Updater - ERROR - Error while calling `get_updates` one more time to mark all fetched updates as read: %s. Suppressing error to ensure graceful shutdown. When polling for updates is restarted, updates may be fetched again. Please adjust timeouts via `ApplicationBuilder` or the parameter `get_updates_request` of `Bot`.
Traceback (most recent call last):
  File "/home/guillo/trading_ai_monitor_v2/venv/lib/python3.12/site-packages/httpx/_transports/default.py", line 66, in map_httpcore_exceptions
    yield
  File "/home/guillo/trading_ai_monitor_v2/venv/lib/python3.12/site-packages/httpx/_transports/default.py", line 366, in handle_async_request
    resp = await self._pool.handle_async_request(req)
           ^^^^^^^^^^^^^^^^^^^^^^^^^^^^^^^^^^^^^^^^^^
  File "/home/guillo/trading_ai_monitor_v2/venv/lib/python3.12/site-packages/httpcore/_async/connection_pool.py", line 256, in handle_async_request
    raise exc from None
  File "/home/guillo/trading_ai_monitor_v2/venv/lib/python3.12/site-packages/httpcore/_async/connection_pool.py", line 236, in handle_async_request
    response = await connection.handle_async_request(
               ^^^^^^^^^^^^^^^^^^^^^^^^^^^^^^^^^^^^^^
  File "/home/guillo/trading_ai_monitor_v2/venv/lib/python3.12/site-packages/httpcore/_async/connection.py", line 101, in handle_async_request
    raise exc
  File "/home/guillo/trading_ai_monitor_v2/venv/lib/python3.12/site-packages/httpcore/_async/connection.py", line 78, in handle_async_request
    stream = await self._connect(request)
             ^^^^^^^^^^^^^^^^^^^^^^^^^^^^
  File "/home/guillo/trading_ai_monitor_v2/venv/lib/python3.12/site-packages/httpcore/_async/connection.py", line 124, in _connect
    stream = await self._network_backend.connect_tcp(**kwargs)
             ^^^^^^^^^^^^^^^^^^^^^^^^^^^^^^^^^^^^^^^^^^^^^^^^^
  File "/home/guillo/trading_ai_monitor_v2/venv/lib/python3.12/site-packages/httpcore/_backends/auto.py", line 31, in connect_tcp
    return await self._backend.connect_tcp(
           ^^^^^^^^^^^^^^^^^^^^^^^^^^^^^^^^
  File "/home/guillo/trading_ai_monitor_v2/venv/lib/python3.12/site-packages/httpcore/_backends/anyio.py", line 113, in connect_tcp
    with map_exceptions(exc_map):
  File "/usr/lib/python3.12/contextlib.py", line 158, in __exit__
    self.gen.throw(value)
  File "/home/guillo/trading_ai_monitor_v2/venv/lib/python3.12/site-packages/httpcore/_exceptions.py", line 14, in map_exceptions
    raise to_exc(exc) from exc
httpcore.ConnectTimeout

The above exception was the direct cause of the following exception:

Traceback (most recent call last):
  File "/home/guillo/trading_ai_monitor_v2/venv/lib/python3.12/site-packages/telegram/request/_httpxrequest.py", line 268, in do_request
    res = await self._client.request(
          ^^^^^^^^^^^^^^^^^^^^^^^^^^^
  File "/home/guillo/trading_ai_monitor_v2/venv/lib/python3.12/site-packages/httpx/_client.py", line 1530, in request
    return await self.send(request, auth=auth, follow_redirects=follow_redirects)
           ^^^^^^^^^^^^^^^^^^^^^^^^^^^^^^^^^^^^^^^^^^^^^^^^^^^^^^^^^^^^^^^^^^^^^^
  File "/home/guillo/trading_ai_monitor_v2/venv/lib/python3.12/site-packages/httpx/_client.py", line 1617, in send
    response = await self._send_handling_auth(
               ^^^^^^^^^^^^^^^^^^^^^^^^^^^^^^^
  File "/home/guillo/trading_ai_monitor_v2/venv/lib/python3.12/site-packages/httpx/_client.py", line 1645, in _send_handling_auth
    response = await self._send_handling_redirects(
               ^^^^^^^^^^^^^^^^^^^^^^^^^^^^^^^^^^^^
  File "/home/guillo/trading_ai_monitor_v2/venv/lib/python3.12/site-packages/httpx/_client.py", line 1682, in _send_handling_redirects
    response = await self._send_single_request(request)
               ^^^^^^^^^^^^^^^^^^^^^^^^^^^^^^^^^^^^^^^^
  File "/home/guillo/trading_ai_monitor_v2/venv/lib/python3.12/site-packages/httpx/_client.py", line 1719, in _send_single_request
    response = await transport.handle_async_request(request)
               ^^^^^^^^^^^^^^^^^^^^^^^^^^^^^^^^^^^^^^^^^^^^^
  File "/home/guillo/trading_ai_monitor_v2/venv/lib/python3.12/site-packages/httpx/_transports/default.py", line 365, in handle_async_request
    with map_httpcore_exceptions():
  File "/usr/lib/python3.12/contextlib.py", line 158, in __exit__
    self.gen.throw(value)
  File "/home/guillo/trading_ai_monitor_v2/venv/lib/python3.12/site-packages/httpx/_transports/default.py", line 83, in map_httpcore_exceptions
    raise mapped_exc(message) from exc
httpx.ConnectTimeout

The above exception was the direct cause of the following exception:

Traceback (most recent call last):
  File "/home/guillo/trading_ai_monitor_v2/venv/lib/python3.12/site-packages/telegram/ext/_updater.py", line 433, in _get_updates_cleanup
    await self.bot.get_updates(
  File "/home/guillo/trading_ai_monitor_v2/venv/lib/python3.12/site-packages/telegram/ext/_extbot.py", line 558, in get_updates
    updates = await super().get_updates(
              ^^^^^^^^^^^^^^^^^^^^^^^^^^
  File "/home/guillo/trading_ai_monitor_v2/venv/lib/python3.12/site-packages/telegram/_bot.py", line 525, in decorator
    result = await func(self, *args, **kwargs)  # skipcq: PYL-E1102
             ^^^^^^^^^^^^^^^^^^^^^^^^^^^^^^^^^
  File "/home/guillo/trading_ai_monitor_v2/venv/lib/python3.12/site-packages/telegram/_bot.py", line 3584, in get_updates
    await self._post(
  File "/home/guillo/trading_ai_monitor_v2/venv/lib/python3.12/site-packages/telegram/_bot.py", line 613, in _post
    return await self._do_post(
           ^^^^^^^^^^^^^^^^^^^^
  File "/home/guillo/trading_ai_monitor_v2/venv/lib/python3.12/site-packages/telegram/ext/_extbot.py", line 340, in _do_post
    return await super()._do_post(
           ^^^^^^^^^^^^^^^^^^^^^^^
  File "/home/guillo/trading_ai_monitor_v2/venv/lib/python3.12/site-packages/telegram/_bot.py", line 641, in _do_post
    return await request.post(
           ^^^^^^^^^^^^^^^^^^^
  File "/home/guillo/trading_ai_monitor_v2/venv/lib/python3.12/site-packages/telegram/request/_baserequest.py", line 200, in post
    result = await self._request_wrapper(
             ^^^^^^^^^^^^^^^^^^^^^^^^^^^^
  File "/home/guillo/trading_ai_monitor_v2/venv/lib/python3.12/site-packages/telegram/request/_baserequest.py", line 340, in _request_wrapper
    raise exc
  File "/home/guillo/trading_ai_monitor_v2/venv/lib/python3.12/site-packages/telegram/request/_baserequest.py", line 330, in _request_wrapper
    code, payload = await self.do_request(
                    ^^^^^^^^^^^^^^^^^^^^^^
  File "/home/guillo/trading_ai_monitor_v2/venv/lib/python3.12/site-packages/telegram/request/_httpxrequest.py", line 285, in do_request
    raise TimedOut from err
telegram.error.TimedOut: Timed out
2025-10-24 08:01:13 - notifier - ERROR - ❌ Error enviando alerta a Telegram: Timed out
2025-10-25 12:58:27 - indicators - ERROR - Bybit API error: Not supported symbols
2025-10-25 12:58:27 - indicators - ERROR - Bybit API error: Not supported symbols
2025-10-25 12:58:29 - indicators - ERROR - Bybit API error: Not supported symbols
2025-10-25 12:58:29 - indicators - ERROR - ❌ No se pudo analizar ningún timeframe para UB/USDT
2025-10-25 12:58:29 - database - ERROR - ❌ Error guardando señal en base de datos: table signals has no column named leverage
2025-10-25 12:58:29 - signal_manager - ERROR - ❌ No se pudo guardar señal en BD: UB/USDT
2025-10-25 12:58:29 - __main__ - ERROR - ❌ Error procesando señal: UB/USDT
2025-10-25 12:58:29 - notifier - ERROR - ✅ Notificación de error enviada: Procesamiento de señal
2025-10-25 22:50:23 - __main__ - ERROR - ❌ Error en startup: 'TelegramUserClient' object has no attribute 'set_signal_callback'
2025-10-25 22:50:23 - notifier - ERROR - ✅ Notificación de error enviada: Startup del sistema
2025-10-25 22:50:23 - __main__ - ERROR - ❌ Error en bucle principal: 'TelegramUserClient' object has no attribute 'set_signal_callback'
2025-10-25 23:03:53 - telegram.ext.Application - CRITICAL - Fetching updates was aborted due to CancelledError(). Suppressing exception to ensure graceful shutdown.
Traceback (most recent call last):
  File "/home/guillo/venv/lib/python3.12/site-packages/telegram/ext/_application.py", line 673, in stop
    self.__update_fetcher_task.result()
  File "/home/guillo/venv/lib/python3.12/site-packages/telegram/ext/_application.py", line 1233, in _update_fetcher
    await self.__update_fetcher()
  File "/home/guillo/venv/lib/python3.12/site-packages/telegram/ext/_application.py", line 1212, in __update_fetcher
    update = await self.update_queue.get()
             ^^^^^^^^^^^^^^^^^^^^^^^^^^^^^
  File "/usr/lib/python3.12/asyncio/queues.py", line 158, in get
    await getter
asyncio.exceptions.CancelledError
2025-10-25 23:11:24 - telegram_client - ERROR - ❌ Error iniciando listener de Telegram: invalid literal for int() with base 10: '--1001774144094'
2025-10-25 23:11:24 - __main__ - ERROR - ❌ Error en listener de Telegram: invalid literal for int() with base 10: '--1001774144094'
2025-10-25 23:14:52 - telegram.ext.Application - CRITICAL - Fetching updates was aborted due to CancelledError(). Suppressing exception to ensure graceful shutdown.
Traceback (most recent call last):
  File "/home/guillo/venv/lib/python3.12/site-packages/telegram/ext/_application.py", line 673, in stop
    self.__update_fetcher_task.result()
  File "/home/guillo/venv/lib/python3.12/site-packages/telegram/ext/_application.py", line 1233, in _update_fetcher
    await self.__update_fetcher()
  File "/home/guillo/venv/lib/python3.12/site-packages/telegram/ext/_application.py", line 1212, in __update_fetcher
    update = await self.update_queue.get()
             ^^^^^^^^^^^^^^^^^^^^^^^^^^^^^
  File "/usr/lib/python3.12/asyncio/queues.py", line 158, in get
    await getter
asyncio.exceptions.CancelledError
2025-10-25 23:15:04 - telegram_client - ERROR - ❌ Error iniciando listener de Telegram: invalid literal for int() with base 10: '--1001774144094'
2025-10-25 23:15:04 - __main__ - ERROR - ❌ Error en listener de Telegram: invalid literal for int() with base 10: '--1001774144094'
2025-10-25 23:15:12 - telegram.ext.Application - CRITICAL - Fetching updates was aborted due to CancelledError(). Suppressing exception to ensure graceful shutdown.
Traceback (most recent call last):
  File "/home/guillo/venv/lib/python3.12/site-packages/telegram/ext/_application.py", line 673, in stop
    self.__update_fetcher_task.result()
  File "/home/guillo/venv/lib/python3.12/site-packages/telegram/ext/_application.py", line 1233, in _update_fetcher
    await self.__update_fetcher()
  File "/home/guillo/venv/lib/python3.12/site-packages/telegram/ext/_application.py", line 1212, in __update_fetcher
    update = await self.update_queue.get()
             ^^^^^^^^^^^^^^^^^^^^^^^^^^^^^
  File "/usr/lib/python3.12/asyncio/queues.py", line 158, in get
    await getter
asyncio.exceptions.CancelledError
2025-10-25 23:41:14 - telegram.ext.Application - CRITICAL - Fetching updates was aborted due to CancelledError(). Suppressing exception to ensure graceful shutdown.
Traceback (most recent call last):
  File "/home/guillo/venv/lib/python3.12/site-packages/telegram/ext/_application.py", line 673, in stop
    self.__update_fetcher_task.result()
  File "/home/guillo/venv/lib/python3.12/site-packages/telegram/ext/_application.py", line 1233, in _update_fetcher
    await self.__update_fetcher()
  File "/home/guillo/venv/lib/python3.12/site-packages/telegram/ext/_application.py", line 1212, in __update_fetcher
    update = await self.update_queue.get()
             ^^^^^^^^^^^^^^^^^^^^^^^^^^^^^
  File "/usr/lib/python3.12/asyncio/queues.py", line 158, in get
    await getter
asyncio.exceptions.CancelledError
2025-10-25 23:49:19 - notifier - ERROR - ❌ Error configurando comandos: name 'application' is not defined
2025-10-26 00:32:47 - telegram.ext.Application - CRITICAL - Fetching updates was aborted due to CancelledError(). Suppressing exception to ensure graceful shutdown.
Traceback (most recent call last):
  File "/home/guillo/venv/lib/python3.12/site-packages/telegram/ext/_application.py", line 673, in stop
    self.__update_fetcher_task.result()
  File "/home/guillo/venv/lib/python3.12/site-packages/telegram/ext/_application.py", line 1233, in _update_fetcher
    await self.__update_fetcher()
  File "/home/guillo/venv/lib/python3.12/site-packages/telegram/ext/_application.py", line 1212, in __update_fetcher
    update = await self.update_queue.get()
             ^^^^^^^^^^^^^^^^^^^^^^^^^^^^^
  File "/usr/lib/python3.12/asyncio/queues.py", line 158, in get
    await getter
asyncio.exceptions.CancelledError
2025-10-26 00:50:14 - telegram.ext.Application - CRITICAL - Fetching updates was aborted due to CancelledError(). Suppressing exception to ensure graceful shutdown.
Traceback (most recent call last):
  File "/home/guillo/venv/lib/python3.12/site-packages/telegram/ext/_application.py", line 673, in stop
    self.__update_fetcher_task.result()
  File "/home/guillo/venv/lib/python3.12/site-packages/telegram/ext/_application.py", line 1233, in _update_fetcher
    await self.__update_fetcher()
  File "/home/guillo/venv/lib/python3.12/site-packages/telegram/ext/_application.py", line 1212, in __update_fetcher
    update = await self.update_queue.get()
             ^^^^^^^^^^^^^^^^^^^^^^^^^^^^^
  File "/usr/lib/python3.12/asyncio/queues.py", line 158, in get
    await getter
asyncio.exceptions.CancelledError
2025-10-26 01:09:11 - notifier - ERROR - ❌ Error configurando comandos: cannot import name 'start_command' from 'commands' (/home/guillo/trading_ai_monitor_v2/commands.py)
2025-10-26 01:09:11 - __main__ - ERROR - ❌ Error configurando comandos de Telegram: cannot import name 'start_command' from 'commands' (/home/guillo/trading_ai_monitor_v2/commands.py)
2025-10-26 01:09:11 - __main__ - ERROR - ❌ Error en startup: cannot import name 'start_command' from 'commands' (/home/guillo/trading_ai_monitor_v2/commands.py)
2025-10-26 01:09:11 - notifier - ERROR - ✅ Notificación de error enviada: Startup del sistema
2025-10-26 01:09:11 - __main__ - ERROR - ❌ Error en bucle principal: cannot import name 'start_command' from 'commands' (/home/guillo/trading_ai_monitor_v2/commands.py)
2025-10-26 01:09:11 - __main__ - ERROR - ❌ Error en shutdown: This Updater is not running!
2025-10-26 02:14:07 - notifier - ERROR - ❌ Error configurando comandos: cannot import name 'start_command' from 'commands' (/home/guillo/trading_ai_monitor_v2/commands.py)
2025-10-26 02:14:07 - __main__ - ERROR - ❌ Error configurando comandos de Telegram: cannot import name 'start_command' from 'commands' (/home/guillo/trading_ai_monitor_v2/commands.py)
2025-10-26 02:14:07 - __main__ - ERROR - ❌ Error en startup: cannot import name 'start_command' from 'commands' (/home/guillo/trading_ai_monitor_v2/commands.py)
2025-10-26 02:14:07 - notifier - ERROR - ✅ Notificación de error enviada: Startup del sistema
2025-10-26 02:14:07 - __main__ - ERROR - ❌ Error en bucle principal: cannot import name 'start_command' from 'commands' (/home/guillo/trading_ai_monitor_v2/commands.py)
2025-10-26 02:14:07 - __main__ - ERROR - ❌ Error en shutdown: This Updater is not running!
2025-10-26 02:19:29 - notifier - ERROR - ❌ Error configurando comandos: cannot import name 'start_command' from 'commands' (/home/guillo/trading_ai_monitor_v2/commands.py)
2025-10-26 02:19:29 - __main__ - ERROR - ❌ Error configurando comandos de Telegram: cannot import name 'start_command' from 'commands' (/home/guillo/trading_ai_monitor_v2/commands.py)
2025-10-26 02:19:29 - __main__ - ERROR - ❌ Error en startup: cannot import name 'start_command' from 'commands' (/home/guillo/trading_ai_monitor_v2/commands.py)
2025-10-26 02:19:29 - notifier - ERROR - ✅ Notificación de error enviada: Startup del sistema
2025-10-26 02:19:29 - __main__ - ERROR - ❌ Error en bucle principal: cannot import name 'start_command' from 'commands' (/home/guillo/trading_ai_monitor_v2/commands.py)
2025-10-26 02:19:29 - __main__ - ERROR - ❌ Error en shutdown: This Updater is not running!
2025-10-26 03:11:52 - trend_analysis - ERROR - ❌ Error en análisis de HUSDT: 'entry'
2025-10-26 03:11:52 - database - ERROR - ❌ Error guardando señal en base de datos: table signals has no column named leverage
2025-10-26 03:11:52 - signal_manager - ERROR - ❌ No se pudo guardar señal en BD: HUSDT
2025-10-26 03:11:52 - __main__ - ERROR - ❌ Error procesando señal: HUSDT
2025-10-26 03:11:52 - notifier - ERROR - ✅ Notificación de error enviada: Procesamiento de señal
2025-10-26 03:50:58 - trend_analysis - ERROR - ❌ Error en análisis de HUSDT: 'entry'
2025-10-26 03:50:58 - database - ERROR - ❌ Error guardando señal en base de datos: table signals has no column named leverage
2025-10-26 03:50:58 - signal_manager - ERROR - ❌ No se pudo guardar señal en BD: HUSDT
2025-10-26 03:50:58 - __main__ - ERROR - ❌ Error procesando señal: HUSDT
2025-10-26 03:50:59 - notifier - ERROR - ✅ Notificación de error enviada: Procesamiento de señal
2025-10-26 04:34:55 - indicators - ERROR - Bybit API error: Not supported symbols
2025-10-26 04:34:56 - indicators - ERROR - Bybit API error: Not supported symbols
2025-10-26 04:34:56 - indicators - ERROR - Bybit API error: Not supported symbols
2025-10-26 04:34:56 - indicators - ERROR - ❌ No se pudo analizar ningún timeframe para AKTUSDT
2025-10-26 04:34:56 - database - ERROR - ❌ Error guardando señal en base de datos: table signals has no column named leverage
2025-10-26 04:34:56 - signal_manager - ERROR - ❌ No se pudo guardar señal en BD: AKTUSDT
2025-10-26 04:34:56 - __main__ - ERROR - ❌ Error procesando señal: AKTUSDT
2025-10-26 04:34:57 - notifier - ERROR - ✅ Notificación de error enviada: Procesamiento de señal
2025-10-26 04:40:59 - trend_analysis - ERROR - ❌ Error en análisis de RECALLUSDT: 'entry'
2025-10-26 04:40:59 - database - ERROR - ❌ Error guardando señal en base de datos: table signals has no column named leverage
2025-10-26 04:40:59 - signal_manager - ERROR - ❌ No se pudo guardar señal en BD: RECALLUSDT
2025-10-26 04:40:59 - __main__ - ERROR - ❌ Error procesando señal: RECALLUSDT
2025-10-26 04:41:00 - notifier - ERROR - ✅ Notificación de error enviada: Procesamiento de señal
2025-10-26 04:45:42 - indicators - ERROR - Bybit API error: Not supported symbols
2025-10-26 04:45:42 - indicators - ERROR - Bybit API error: Not supported symbols
2025-10-26 04:45:43 - indicators - ERROR - Bybit API error: Not supported symbols
2025-10-26 04:45:43 - indicators - ERROR - ❌ No se pudo analizar ningún timeframe para AKTUSDT
2025-10-26 04:45:43 - database - ERROR - ❌ Error guardando señal en base de datos: table signals has no column named leverage
2025-10-26 04:45:43 - signal_manager - ERROR - ❌ No se pudo guardar señal en BD: AKTUSDT
2025-10-26 04:45:43 - __main__ - ERROR - ❌ Error procesando señal: AKTUSDT
2025-10-26 04:45:43 - notifier - ERROR - ✅ Notificación de error enviada: Procesamiento de señal
2025-10-26 04:49:19 - indicators - ERROR - Bybit API error: Not supported symbols
2025-10-26 04:49:20 - indicators - ERROR - Bybit API error: Not supported symbols
2025-10-26 04:49:20 - indicators - ERROR - Bybit API error: Not supported symbols
2025-10-26 04:49:20 - indicators - ERROR - ❌ No se pudo analizar ningún timeframe para AKTUSDT
2025-10-26 04:49:20 - database - ERROR - ❌ Error guardando señal en base de datos: table signals has no column named leverage
2025-10-26 04:49:20 - signal_manager - ERROR - ❌ No se pudo guardar señal en BD: AKTUSDT
2025-10-26 04:49:20 - __main__ - ERROR - ❌ Error procesando señal: AKTUSDT
2025-10-26 04:49:21 - notifier - ERROR - ✅ Notificación de error enviada: Procesamiento de señal
2025-10-26 04:50:49 - indicators - ERROR - Bybit API error: Not supported symbols
2025-10-26 04:50:50 - indicators - ERROR - Bybit API error: Not supported symbols
2025-10-26 04:50:50 - indicators - ERROR - Bybit API error: Not supported symbols
2025-10-26 04:50:50 - indicators - ERROR - ❌ No se pudo analizar ningún timeframe para AKTUSDT
2025-10-26 04:50:50 - database - ERROR - ❌ Error guardando señal en base de datos: table signals has no column named leverage
2025-10-26 04:50:50 - signal_manager - ERROR - ❌ No se pudo guardar señal en BD: AKTUSDT
2025-10-26 04:50:50 - __main__ - ERROR - ❌ Error procesando señal: AKTUSDT
2025-10-26 04:50:51 - notifier - ERROR - ✅ Notificación de error enviada: Procesamiento de señal
2025-10-26 05:01:26 - trend_analysis - ERROR - ❌ Error en análisis de RECALLUSDT: 'entry'
2025-10-26 05:01:26 - database - ERROR - ❌ Error guardando señal en base de datos: table signals has no column named leverage
2025-10-26 05:01:26 - signal_manager - ERROR - ❌ No se pudo guardar señal en BD: RECALLUSDT
2025-10-26 05:01:26 - __main__ - ERROR - ❌ Error procesando señal: RECALLUSDT
2025-10-26 05:01:26 - notifier - ERROR - ✅ Notificación de error enviada: Procesamiento de señal
2025-10-26 05:14:12 - trend_analysis - ERROR - ❌ Error en análisis de RECALLUSDT: 'entry'
2025-10-26 05:14:12 - database - ERROR - ❌ Error guardando señal en base de datos: table signals has no column named leverage
2025-10-26 05:14:12 - signal_manager - ERROR - ❌ No se pudo guardar señal en BD: RECALLUSDT
2025-10-26 05:14:12 - __main__ - ERROR - ❌ Error procesando señal: RECALLUSDT
2025-10-26 05:14:13 - notifier - ERROR - ✅ Notificación de error enviada: Procesamiento de señal
2025-10-26 05:20:46 - indicators - ERROR - Bybit API error: Not supported symbols
2025-10-26 05:20:47 - indicators - ERROR - Bybit API error: Not supported symbols
2025-10-26 05:20:47 - indicators - ERROR - Bybit API error: Not supported symbols
2025-10-26 05:20:47 - indicators - ERROR - ❌ No se pudo analizar ningún timeframe para AKTUSDT
2025-10-26 05:20:47 - database - ERROR - ❌ Error guardando señal en base de datos: table signals has no column named leverage
2025-10-26 05:20:47 - signal_manager - ERROR - ❌ No se pudo guardar señal en BD: AKTUSDT
2025-10-26 05:20:47 - __main__ - ERROR - ❌ Error procesando señal: AKTUSDT
2025-10-26 05:20:48 - notifier - ERROR - ✅ Notificación de error enviada: Procesamiento de señal
2025-10-26 18:56:15 - indicators - ERROR - Bybit API error: Not supported symbols
2025-10-26 18:56:15 - indicators - ERROR - Bybit API error: Not supported symbols
2025-10-26 18:56:16 - indicators - ERROR - Bybit API error: Not supported symbols
2025-10-26 18:56:16 - indicators - ERROR - ❌ No se pudo analizar ningún timeframe para UBUSDT
2025-10-26 18:56:16 - database - ERROR - ❌ Error guardando señal en base de datos: table signals has no column named leverage
2025-10-26 18:56:16 - signal_manager - ERROR - ❌ No se pudo guardar señal en BD: UBUSDT
2025-10-26 18:56:16 - __main__ - ERROR - ❌ Error procesando señal: UBUSDT
2025-10-26 18:56:16 - indicators - ERROR - Bybit API error: Not supported symbols
2025-10-26 18:56:17 - indicators - ERROR - Bybit API error: Not supported symbols
2025-10-26 18:56:17 - indicators - ERROR - Bybit API error: Not supported symbols
2025-10-26 18:56:17 - indicators - ERROR - ❌ No se pudo analizar ningún timeframe para UBUSDT
2025-10-26 18:56:17 - database - ERROR - ❌ Error guardando señal en base de datos: table signals has no column named leverage
2025-10-26 18:56:17 - signal_manager - ERROR - ❌ No se pudo guardar señal en BD: UBUSDT
2025-10-26 18:56:17 - __main__ - ERROR - ❌ Error procesando señal: UBUSDT
2025-10-26 18:56:18 - indicators - ERROR - Bybit API error: Not supported symbols
2025-10-26 18:56:19 - indicators - ERROR - Bybit API error: Not supported symbols
2025-10-26 18:56:19 - indicators - ERROR - Bybit API error: Not supported symbols
2025-10-26 18:56:19 - indicators - ERROR - ❌ No se pudo analizar ningún timeframe para UBUSDT
2025-10-26 18:56:19 - database - ERROR - ❌ Error guardando señal en base de datos: table signals has no column named leverage
2025-10-26 18:56:19 - signal_manager - ERROR - ❌ No se pudo guardar señal en BD: UBUSDT
2025-10-26 18:56:19 - __main__ - ERROR - ❌ Error procesando señal: UBUSDT
2025-10-26 18:56:20 - notifier - ERROR - ✅ Notificación de error enviada: Procesamiento de señal
2025-10-26 18:56:20 - notifier - ERROR - ✅ Notificación de error enviada: Procesamiento de señal
2025-10-26 18:56:20 - notifier - ERROR - ✅ Notificación de error enviada: Procesamiento de señal
2025-10-27 02:43:09 - telegram.ext.Application - CRITICAL - Fetching updates was aborted due to CancelledError(). Suppressing exception to ensure graceful shutdown.
Traceback (most recent call last):
  File "/home/guillo/venv/lib/python3.12/site-packages/telegram/ext/_application.py", line 673, in stop
    self.__update_fetcher_task.result()
  File "/home/guillo/venv/lib/python3.12/site-packages/telegram/ext/_application.py", line 1233, in _update_fetcher
    await self.__update_fetcher()
  File "/home/guillo/venv/lib/python3.12/site-packages/telegram/ext/_application.py", line 1212, in __update_fetcher
    update = await self.update_queue.get()
             ^^^^^^^^^^^^^^^^^^^^^^^^^^^^^
  File "/usr/lib/python3.12/asyncio/queues.py", line 158, in get
    await getter
asyncio.exceptions.CancelledError
2025-10-28 20:56:27 - telegram.ext.Application - CRITICAL - Fetching updates was aborted due to CancelledError(). Suppressing exception to ensure graceful shutdown.
Traceback (most recent call last):
  File "/home/guillo/venv/lib/python3.12/site-packages/telegram/ext/_application.py", line 673, in stop
    self.__update_fetcher_task.result()
  File "/home/guillo/venv/lib/python3.12/site-packages/telegram/ext/_application.py", line 1233, in _update_fetcher
    await self.__update_fetcher()
  File "/home/guillo/venv/lib/python3.12/site-packages/telegram/ext/_application.py", line 1212, in __update_fetcher
    update = await self.update_queue.get()
             ^^^^^^^^^^^^^^^^^^^^^^^^^^^^^
  File "/usr/lib/python3.12/asyncio/queues.py", line 158, in get
    await getter
asyncio.exceptions.CancelledError
